Workbook

Sheet 1 Inputs
A1: DESIGN INPUTS
A4: MILK (PROCESS STREAM)
A5: Description | B5: Value | C5: Unit | D5: Notes
A6: Milk inlet velocity | B6: 2 | C6: m/s | D6: Upper Limit of 1 m/s, what can be changed in the experimental setup.
A8: Milk inlet temperature | B8: 6 | C8: degC | D8: Raw milk ex chilled storage (4-10 degC typical).
A9: Inlet milk solids concentration | B9: 0.12 | C9: kg/kg | D9: Raw whole milk ~ 12-13 wt% total solids. Enter as a fraction (0.12 = 12%).
A10: Liquid specific heat capacity | B10: 4.186 | C10: kJ/(kg.K) | D10: ASSUMPTION: milk treated as pure water throughout.
A11: Liquid density | B11: 1000 | C11: kg/m3 | D11: ASSUMPTION: milk treated as pure water. Used for the mass-flow conversion and velocity checks.
A12: Milk mass flow, Derived | B12: ='1 Inputs'!$B$11*(PI()*'1 Inputs'!$B$24^2/4)*'1 Inputs'!$B$6*3600 -> 14137.167 | C12: kg/h
A14: STEAM (HEATING MEDIUM)
A15: Description | B15: Value | C15: Unit | D15: Notes / source
A16: Steam supply pressure (absolute) | B16: 6 | C16: bar(a) | D16: Dry saturated steam assumed, so temperature is fixed by pressure (sheet 2). Table valid 1-10 bar(a).
A17: Steam mass flow injected | B17: 1590 | C17: kg/h | D17: Model input for the forward calculation. For the reverse problem (steam needed for a target temperature) see '5 Steam Sizing'. | F17: Change this to m3/h
A18: Steam nozzle internal diameter | B18: 0.005 | C18: m | D18: Initial assumed single-orifice bore (5 mm), not a rig measurement. Used for the choked-capacity check on '4 Results'.
A19: Steam nozzle velocity limit (~ sonic) | B19: 500 | C19: m/s | D19: Saturated steam sonic velocity is ~480-500 m/s at 1-10 bar; a nozzle cannot pass steam faster than thi
A20: Steam nozzle discharge coefficient, C_d | B20: 0.85 | C20: - | D20: Plain steam orifice; same value as the cross-sectional model. Used for the choked capacity on '4 Results'.
A21: PIPE / INJECTOR
A22: Description | B22: Value | C22: Unit | D22: Notes / source
A23: Pipe length modelled | B23: 2 | C23: m
A24: Pipe internal diameter | B24: 0.05 | C24: m
A25: Steam injection position from inlet | B25: 0.2 | C25: m | D25: All steam condenses at this e point (immediate condensation, complete mixing)
A27: MODEL SETTINGS
A28: Description | B28: Value | C28: Unit | D28: Notes / source
A29: Number of nodes (pipe divisions) | B29: 100 | C29: - | D29: Node spacing = length / nodes. To change the node count see '6 Documentation'.
A30: Target solids after evaporation | B30: 0.12 | C30: kg/kg | D30: Set equal to the inlet solids concentration to restore original composition.
A32: CRITERIA FOR STERILISATION/PASTEURISATION
A33: Description | B33: Value | C33: Unit | D33: Notes / source
A34: Sterilisation temperature (UHT) | B34: 138 | C34: degC | D34: UHT sterilisation: >= 138 degC held >= 2 s
A35: Sterilisation holding time | B35: 2 | C35: s
A36: Pasteurisation temperature (HTST) | B36: 72 | C36: degC | D36: HTST pasteurisation: >= 72 degC held >= 15 s.
A37: Pasteurisation holding time | B37: 15 | C37: s

Sheet 2 Steam Properties
A1: SATURATED STEAM PROPERTIES
A4: PROPERTIES AT THE MODEL STEAM PRESSURE (ALL CALCULATED FROM THE STEAM PRESSURE ON '1 INPUTS')
A5: Steam pressure | B5: ='1 Inputs'!$B$16 -> 6 | C5: bar(a)
A6: Table row index | B6: =MATCH('1 Inputs'!$B$16,$A$30:$A$45,1) -> 10 | C6: - | D6: Largest table pressure <= supply pressure (table sorted ascending).
A7: Lower bracketing pressure P1 | B7: =INDEX($A$30:$A$45,'2 Steam Properties'!$B$6) -> 6 | C7: bar(a)
A8: Upper bracketing pressure P2 | B8: =INDEX($A$30:$A$45,'2 Steam Properties'!$B$6+1) -> 7 | C8: bar(a)
A9: Interpolation fraction f = (P-P1)/(P2-P1) | B9: =('1 Inputs'!$B$16-'2 Steam Properties'!$B$7)/('2 Steam Properties'!$B$8-'2 Steam Properties'!$B$7) -> 0 | C9: - | D9: 0 <= f < 1; f = 0 when the pressure lands exactly on a table row.
A10: Saturation temperature | B10: =INDEX($B$30:$B$45,'2 Steam Properties'!$B$6)+'2 Steam Properties'!$B$9*(INDEX($B$30:$B$45,'2 Steam Properties'!$B$6+1)-INDEX($B$30:$B$45,'2 Steam Properties'!$B$6)) -> 158.83 | C10: degC | D10: This IS the steam temperature (saturated steam).
A11: Saturated liquid enthalpy (h_f) | B11: =INDEX($C$30:$C$45,'2 Steam Properties'!$B$6)+'2 Steam Properties'!$B$9*(INDEX($C$30:$C$45,'2 Steam Properties'!$B$6+1)-INDEX($C$30:$C$45,'2 Steam Properties'!$B$6)) -> 670.5 | C11: kJ/kg | D11: Condensate enthalpy at the supply pressure.
A12: Latent heat of vaporisation (h_fg) | B12: =INDEX($D$30:$D$45,'2 Steam Properties'!$B$6)+'2 Steam Properties'!$B$9*(INDEX($D$30:$D$45,'2 Steam Properties'!$B$6+1)-INDEX($D$30:$D$45,'2 Steam Properties'!$B$6)) -> 2085.6 | C12: kJ/kg | D12: Heat released per kg condensed.
A13: Saturated vapour enthalpy (h_g) | B13: =INDEX($E$30:$E$45,'2 Steam Properties'!$B$6)+'2 Steam Properties'!$B$9*(INDEX($E$30:$E$45,'2 Steam Properties'!$B$6+1)-INDEX($E$30:$E$45,'2 Steam Properties'!$B$6)) -> 2756.1 | C13: kJ/kg | D13: Enthalpy carried in per kg of injected steam — used in the node energy balance.
A14: Saturated vapour specific volume (v_g) | B14: =INDEX($F$30:$F$45,'2 Steam Properties'!$B$6)+'2 Steam Properties'!$B$9*(INDEX($F$30:$F$45,'2 Steam Properties'!$B$6+1)-INDEX($F$30:$F$45,'2 Steam Properties'!$B$6)) -> 0.3156 | C14: m3/kg | D14: Used for the steam nozzle velocity check: velocity = steam flow x v_g / nozzle area.
A15: Consistency check h_g - (h_f + h_fg) | B15: ='2 Steam Properties'!$B$13-('2 Steam Properties'!$B$11+'2 Steam Properties'!$B$12) -> 0 | C15: kJ/kg | D15: Should be ~ 0 (rounding only).
A17: STAND-ALONE INTERPOLATION CALCULATOR
A18: Pressure of interest | B18: 2.7 | C18: bar(a) | D18: Editable. Valid 1-10 bar(a).
A19: Row index k* | B19: =MATCH($B$18,$A$30:$A$45,1) -> 4 | C19: - | D19: Bracketing row (largest table pressure <= P*).
A20: Fraction f* = (P*-P1)/(P2-P1) | B20: =($B$18-INDEX($A$30:$A$45,$B$19))/(INDEX($A$30:$A$45,$B$19+1)-INDEX($A$30:$A$45,$B$19)) -> 0.4 | C20: -
A21: Saturation temperature* | B21: =INDEX($B$30:$B$45,$B$19)+$B$20*(INDEX($B$30:$B$45,$B$19+1)-INDEX($B$30:$B$45,$B$19)) -> 129.858 | C21: degC
A22: Sat. liquid enthalpy h_f* | B22: =INDEX($C$30:$C$45,$B$19)+$B$20*(INDEX($C$30:$C$45,$B$19+1)-INDEX($C$30:$C$45,$B$19)) -> 545.794 | C22: kJ/kg
A23: Latent heat h_fg* | B23: =INDEX($D$30:$D$45,$B$19)+$B$20*(INDEX($D$30:$D$45,$B$19+1)-INDEX($D$30:$D$45,$B$19)) -> 2174.08 | C23: kJ/kg
A24: Sat. vapour enthalpy h_g* | B24: =INDEX($E$30:$E$45,$B$19)+$B$20*(INDEX($E$30:$E$45,$B$19+1)-INDEX($E$30:$E$45,$B$19)) -> 2719.86 | C24: kJ/kg
A25: Sat. vapour specific volume v_g* | B25: =INDEX($F$30:$F$45,$B$19)+$B$20*(INDEX($F$30:$F$45,$B$19+1)-INDEX($F$30:$F$45,$B$19)) -> 0.67354 | C25: m3/kg
A28: SATURATED STEAM TABLE (REFERENCE DATA)
A29: P (bar a) | B29: T_sat (degC) | C29: h_f (kJ/kg) | D29: h_fg (kJ/kg) | E29: h_g (kJ/kg) | F29: v_g (m3/kg)
A30: 1 | B30: 99.61 | C30: 417.44 | D30: 2257.5 | E30: 2674.9 | F30: 1.694
A31: 1.5 | B31: 111.35 | C31: 467.08 | D31: 2226 | E31: 2693.1 | F31: 1.1594
A32: 2 | B32: 120.21 | C32: 504.68 | D32: 2201.6 | E32: 2706.2 | F32: 0.8857
A33: 2.5 | B33: 127.41 | C33: 535.35 | D33: 2181.2 | E33: 2716.5 | F33: 0.7187
A34: 3 | B34: 133.53 | C34: 561.46 | D34: 2163.4 | E34: 2724.9 | F34: 0.6058
A35: 3.5 | B35: 138.86 | C35: 584.31 | D35: 2147.7 | E35: 2732 | F35: 0.5242
A36: 4 | B36: 143.61 | C36: 604.72 | D36: 2133.3 | E36: 2738.1 | F36: 0.4624
A37: 4.5 | B37: 147.91 | C37: 623.22 | D37: 2120.2 | E37: 2743.4 | F37: 0.4139
A38: 5 | B38: 151.84 | C38: 640.19 | D38: 2107.9 | E38: 2748.1 | F38: 0.3748
A39: 6 | B39: 158.83 | C39: 670.5 | D39: 2085.6 | E39: 2756.1 | F39: 0.3156
A40: 7 | B40: 164.95 | C40: 697.14 | D40: 2065.6 | E40: 2762.7 | F40: 0.2728
A41: 8 | B41: 170.41 | C41: 721.02 | D41: 2047.3 | E41: 2768.3 | F41: 0.2403
... A45: 12 | B45: 187.96 | C45: 798.5 | D45: 1985.3 | E45: 2783.8 | F45: 0.1632
A47: Source: IAPWS-IF97 industrial formulation (Wagner & Kretzschmar, International Steam Tables, 2nd ed., 2008), the same values as the cross-sectional model. Rows at 11 and 12 bar
A48: exist only so interpolation stays defined up to 10 bar; the stated valid range is 1-10 bar(a).

Sheet 3 Node Calculations
A1: NODE-BY-NODE FINITE DIFFERENCE CALCULATIONS
A2: Each row is one node; every node applies a steady-state mass, solids and energy balance to the previous node (marching inlet -> outlet).
A3: Node 0 is the inlet boundary condition. Everything below is a formula referencing sheets 1 and 2 — no hard-coded numbers.
A6: DERIVED MODEL PARAMETERS (CALCULATED — DO NOT EDIT)
A7: Node spacing = pipe length / node count | G7: ='1 Inputs'!$B$23/'1 Inputs'!$B$29 -> 0.02 | H7: m
A8: Pipe cross-section area = pi x diameter^2 / 4 | G8: =PI()*'1 Inputs'!$B$24^2/4 -> 0.0019634954 | H8: m2
A9: Nozzle cross-section area = pi x bore^2 / 4 | G9: =PI()*'1 Inputs'!$B$18^2/4 -> 1.9634954e-05 | H9: m2
A10: Milk mass flow = density x pipe area x velocity | G10: ='1 Inputs'!$B$11*'3 Node Calculations'!$G$8*'1 Inputs'!$B$6 -> 3.9269908 | H10: kg/s
A11: Steam mass flow = steam flow [kg/h] / 3600 | G11: ='1 Inputs'!$B$17/3600 -> 0.44166667 | H11: kg/s
A12: Solids mass flow = milk flow x inlet solids (constant) | G12: ='3 Node Calculations'!$G$10*'1 Inputs'!$B$9 -> 0.4712389 | H12: kg/s
A13: Inlet enthalpy flow = milk flow x c_p x inlet temperature (datum 0 degC) | G13: ='3 Node Calculations'!$G$10*'1 Inputs'!$B$10*'1 Inputs'!$B$8 -> 98.630301 | H13: kW
A14: Injection node index = ROUNDUP(injection position / node spacing) (informational) | G14: =ROUNDUP('1 Inputs'!$B$25/'3 Node Calculations'!$G$7,0) -> 10 | H14: -
A16: NODE TABLE
A17: Node i | B17: Distance x | C17: Steam added at node | D17: Cum. steam condensed | E17: Milk feed flow | F17: Total mass flow | G17: Solids mass flow | H17: Water mass flow | I17: Solids concentration | J17: Enthalpy flow | K17: Specific enthalpy | L17: Temperature | M17: Energy balance check
A18: - | B18: m | C18: kg/s | D18: kg/s | E18: kg/s | F18: kg/s | G18: kg/s | H18: kg/s | I18: kg/kg | J18: kW | K18: kJ/kg | L18: degC | M18: kW (=0)
A19: 0 | B19: =A19*'3 Node Calculations'!$G$7 -> 0 | C19: 0 | D19: =C19 -> 0 | E19: ='3 Node Calculations'!$G$10 -> 3.9269908 | F19: =E19+D19 -> 3.9269908 | G19: ='3 Node Calculations'!$G$12 -> 0.4712389 | H19: =F19-G19 -> 3.4557519 | I19: =G19/F19 -> 0.12 | J19: ='3 Node Calculations'!$G$13 -> 98.630301 | K19: =J19/F19 -> 25.116 | L19: =K19/'1 Inputs'!$B$10 -> 6 | M19: 0
A20: =A19+1 -> 1 | B20: =A20*'3 Node Calculations'!$G$7 -> 0.02 | C20: =IF(AND(B20>='1 Inputs'!$B$25,B19<'1 Inputs'!$B$25),'3 Node Calculations'!$G$11,0) -> 0 | D20: =D19+C20 -> 0 | E20: =E19 -> 3.9269908 | F20: =E20+D20 -> 3.9269908 | G20: =G19 -> 0.4712389 | H20: =F20-G20 -> 3.4557519 | I20: =G20/F20 -> 0.12 | J20: =J19+C20*'2 Steam Properties'!$B$13 -> 98.630301 | K20: =J20/F20 -> 25.116 | L20: =K20/'1 Inputs'!$B$10 -> 6 | M20: =J19+C20*'2 Steam Properties'!$B$13-J20 -> 0
A21: =A20+1 -> 2 | B21: =A21*'3 Node Calculations'!$G$7 -> 0.04 | C21: =IF(AND(B21>='1 Inputs'!$B$25,B20<'1 Inputs'!$B$25),'3 Node Calculations'!$G$11,0) -> 0 | D21: =D20+C21 -> 0 | E21: =E20 -> 3.9269908 | F21: =E21+D21 -> 3.9269908 | G21: =G20 -> 0.4712389 | H21: =F21-G21 -> 3.4557519 | I21: =G21/F21 -> 0.12 | J21: =J20+C21*'2 Steam Properties'!$B$13 -> 98.630301 | K21: =J21/F21 -> 25.116 | L21: =K21/'1 Inputs'!$B$10 -> 6 | M21: =J20+C21*'2 Steam Properties'!$B$13-J21 -> 0
A22: =A21+1 -> 3 | B22: =A22*'3 Node Calculations'!$G$7 -> 0.06 | C22: =IF(AND(B22>='1 Inputs'!$B$25,B21<'1 Inputs'!$B$25),'3 Node Calculations'!$G$11,0) -> 0 | D22: =D21+C22 -> 0 | E22: =E21 -> 3.9269908 | F22: =E22+D22 -> 3.9269908 | G22: =G21 -> 0.4712389 | H22: =F22-G22 -> 3.4557519 | I22: =G22/F22 -> 0.12 | J22: =J21+C22*'2 Steam Properties'!$B$13 -> 98.630301 | K22: =J22/F22 -> 25.116 | L22: =K22/'1 Inputs'!$B$10 -> 6 | M22: =J21+C22*'2 Steam Properties'!$B$13-J22 -> 0
A23: =A22+1 -> 4 | B23: =A23*'3 Node Calculations'!$G$7 -> 0.08 | C23: =IF(AND(B23>='1 Inputs'!$B$25,B22<'1 Inputs'!$B$25),'3 Node Calculations'!$G$11,0) -> 0 | D23: =D22+C23 -> 0 | E23: =E22 -> 3.9269908 | F23: =E23+D23 -> 3.9269908 | G23: =G22 -> 0.4712389 | H23: =F23-G23 -> 3.4557519 | I23: =G23/F23 -> 0.12 | J23: =J22+C23*'2 Steam Properties'!$B$13 -> 98.630301 | K23: =J23/F23 -> 25.116 | L23: =K23/'1 Inputs'!$B$10 -> 6 | M23: =J22+C23*'2 Steam Properties'!$B$13-J23 -> 0
A24: =A23+1 -> 5 | B24: =A24*'3 Node Calculations'!$G$7 -> 0.1 | C24: =IF(AND(B24>='1 Inputs'!$B$25,B23<'1 Inputs'!$B$25),'3 Node Calculations'!$G$11,0) -> 0 | D24: =D23+C24 -> 0 | E24: =E23 -> 3.9269908 | F24: =E24+D24 -> 3.9269908 | G24: =G23 -> 0.4712389 | H24: =F24-G24 -> 3.4557519 | I24: =G24/F24 -> 0.12 | J24: =J23+C24*'2 Steam Properties'!$B$13 -> 98.630301 | K24: =J24/F24 -> 25.116 | L24: =K24/'1 Inputs'!$B$10 -> 6 | M24: =J23+C24*'2 Steam Properties'!$B$13-J24 -> 0
A25: =A24+1 -> 6 | B25: =A25*'3 Node Calculations'!$G$7 -> 0.12 | C25: =IF(AND(B25>='1 Inputs'!$B$25,B24<'1 Inputs'!$B$25),'3 Node Calculations'!$G$11,0) -> 0 | D25: =D24+C25 -> 0 | E25: =E24 -> 3.9269908 | F25: =E25+D25 -> 3.9269908 | G25: =G24 -> 0.4712389 | H25: =F25-G25 -> 3.4557519 | I25: =G25/F25 -> 0.12 | J25: =J24+C25*'2 Steam Properties'!$B$13 -> 98.630301 | K25: =J25/F25 -> 25.116 | L25: =K25/'1 Inputs'!$B$10 -> 6 | M25: =J24+C25*'2 Steam Properties'!$B$13-J25 -> 0
A26: =A25+1 -> 7 | B26: =A26*'3 Node Calculations'!$G$7 -> 0.14 | C26: =IF(AND(B26>='1 Inputs'!$B$25,B25<'1 Inputs'!$B$25),'3 Node Calculations'!$G$11,0) -> 0 | D26: =D25+C26 -> 0 | E26: =E25 -> 3.9269908 | F26: =E26+D26 -> 3.9269908 | G26: =G25 -> 0.4712389 | H26: =F26-G26 -> 3.4557519 | I26: =G26/F26 -> 0.12 | J26: =J25+C26*'2 Steam Properties'!$B$13 -> 98.630301 | K26: =J26/F26 -> 25.116 | L26: =K26/'1 Inputs'!$B$10 -> 6 | M26: =J25+C26*'2 Steam Properties'!$B$13-J26 -> 0
A27: =A26+1 -> 8 | B27: =A27*'3 Node Calculations'!$G$7 -> 0.16 | C27: =IF(AND(B27>='1 Inputs'!$B$25,B26<'1 Inputs'!$B$25),'3 Node Calculations'!$G$11,0) -> 0 | D27: =D26+C27 -> 0 | E27: =E26 -> 3.9269908 | F27: =E27+D27 -> 3.9269908 | G27: =G26 -> 0.4712389 | H27: =F27-G27 -> 3.4557519 | I27: =G27/F27 -> 0.12 | J27: =J26+C27*'2 Steam Properties'!$B$13 -> 98.630301 | K27: =J27/F27 -> 25.116 | L27: =K27/'1 Inputs'!$B$10 -> 6 | M27: =J26+C27*'2 Steam Properties'!$B$13-J27 -> 0
A28: =A27+1 -> 9 | B28: =A28*'3 Node Calculations'!$G$7 -> 0.18 | C28: =IF(AND(B28>='1 Inputs'!$B$25,B27<'1 Inputs'!$B$25),'3 Node Calculations'!$G$11,0) -> 0 | D28: =D27+C28 -> 0 | E28: =E27 -> 3.9269908 | F28: =E28+D28 -> 3.9269908 | G28: =G27 -> 0.4712389 | H28: =F28-G28 -> 3.4557519 | I28: =G28/F28 -> 0.12 | J28: =J27+C28*'2 Steam Properties'!$B$13 -> 98.630301 | K28: =J28/F28 -> 25.116 | L28: =K28/'1 Inputs'!$B$10 -> 6 | M28: =J27+C28*'2 Steam Properties'!$B$13-J28 -> 0
A29: =A28+1 -> 10 | B29: =A29*'3 Node Calculations'!$G$7 -> 0.2 | C29: =IF(AND(B29>='1 Inputs'!$B$25,B28<'1 Inputs'!$B$25),'3 Node Calculations'!$G$11,0) -> 0.44166667 | D29: =D28+C29 -> 0.44166667 | E29: =E28 -> 3.9269908 | F29: =E29+D29 -> 4.3686575 | G29: =G28 -> 0.4712389 | H29: =F29-G29 -> 3.8974186 | I29: =G29/F29 -> 0.10786813 | J29: =J28+C29*'2 Steam Properties'!$B$13 -> 1315.9078 | K29: =J29/F29 -> 301.2156 | L29: =K29/'1 Inputs'!$B$10 -> 71.95786 | M29: =J28+C29*'2 Steam Properties'!$B$13-J29 -> 0
A30: =A29+1 -> 11 | B30: =A30*'3 Node Calculations'!$G$7 -> 0.22 | C30: =IF(AND(B30>='1 Inputs'!$B$25,B29<'1 Inputs'!$B$25),'3 Node Calculations'!$G$11,0) -> 0 | D30: =D29+C30 -> 0.44166667 | E30: =E29 -> 3.9269908 | F30: =E30+D30 -> 4.3686575 | G30: =G29 -> 0.4712389 | H30: =F30-G30 -> 3.8974186 | I30: =G30/F30 -> 0.10786813 | J30: =J29+C30*'2 Steam Properties'!$B$13 -> 1315.9078 | K30: =J30/F30 -> 301.2156 | L30: =K30/'1 Inputs'!$B$10 -> 71.95786 | M30: =J29+C30*'2 Steam Properties'!$B$13-J30 -> 0
A31: =A30+1 -> 12 | B31: =A31*'3 Node Calculations'!$G$7 -> 0.24 | C31: =IF(AND(B31>='1 Inputs'!$B$25,B30<'1 Inputs'!$B$25),'3 Node Calculations'!$G$11,0) -> 0 | D31: =D30+C31 -> 0.44166667 | E31: =E30 -> 3.9269908 | F31: =E31+D31 -> 4.3686575 | G31: =G30 -> 0.4712389 | H31: =F31-G31 -> 3.8974186 | I31: =G31/F31 -> 0.10786813 | J31: =J30+C31*'2 Steam Properties'!$B$13 -> 1315.9078 | K31: =J31/F31 -> 301.2156 | L31: =K31/'1 Inputs'!$B$10 -> 71.95786 | M31: =J30+C31*'2 Steam Properties'!$B$13-J31 -> 0
... A119: =A118+1 -> 100 | B119: =A119*'3 Node Calculations'!$G$7 -> 2 | C119: =IF(AND(B119>='1 Inputs'!$B$25,B118<'1 Inputs'!$B$25),'3 Node Calculations'!$G$11,0) -> 0 | D119: =D118+C119 -> 0.44166667 | E119: =E118 -> 3.9269908 | F119: =E119+D119 -> 4.3686575 | G119: =G118 -> 0.4712389 | H119: =F119-G119 -> 3.8974186 | I119: =G119/F119 -> 0.10786813 | J119: =J118+C119*'2 Steam Properties'!$B$13 -> 1315.9078 | K119: =J119/F119 -> 301.2156 | L119: =K119/'1 Inputs'!$B$10 -> 71.95786 | M119: =J118+C119*'2 Steam Properties'!$B$13-J119 -> 0
A121: Column formula documentation (full derivations on '6 Documentation'):
A122: Steam added: IF this node's interval contains the injection position, the whole steam flow is added, else 0.
A123: Cumulative steam: running total. Total mass flow: milk feed + cumulative steam (steady state, no accumulation).
A124: Solids mass flow: constant (solids inert). Solids concentration: solids flow / total flow.
A125: Enthalpy flow: previous + steam added x saturated vapour enthalpy (adiabatic). Datum: liquid at 0 degC.
A126: Specific enthalpy = enthalpy flow / total flow; Temperature = specific enthalpy / c_p (milk as water, constant c_p).
A127: Energy balance check restates the node balance — must be 0 at every node.

Sheet 4 Results
A1: RESULTS SUMMARY
A4: OUTLET CONDITIONS
A5: Quantity | B5: Value | C5: Unit | D5: Basis / equation
A6: Outlet temperature | B6: ='3 Node Calculations'!$L$119 -> 71.95786 | C6: C | D6: Temperature at the last node
A7: Temperature rise (outlet - inlet) | B7: ='3 Node Calculations'!$L$119-'1 Inputs'!$B$8 -> 65.95786 | C7: C | D7: Sensible heating achieved by steam condensation.
A8: Outlet total mass flow | B8: ='3 Node Calculations'!$F$119 -> 4.3686575 | C8: kg/s | D8: Milk feed + condensed steam.
A9: Outlet total mass flow | B9: ='3 Node Calculations'!$F$119*3600 -> 15727.167 | C9: kg/h
A10: Outlet solids concentration | B10: ='3 Node Calculations'!$I$119 -> 0.10786813 | C10: kg/kg
A11: Outlet milk velocity = flow / (density x area) | B11: ='3 Node Calculations'!$F$119/('1 Inputs'!$B$11*'3 Node Calculations'!$G$8) -> 2.224939 | C11: m/s
A12: Steam nozzle velocity = steam flow x v_g / nozzle area | B12: ='3 Node Calculations'!$G$11*'2 Steam Properties'!$B$14/'3 Node Calculations'!$G$9 -> 7099.0744 | C12: m/s
A14: STEAM / WATER ADDED
A15: Quantity | B15: Value | C15: Unit | D15: Basis / equation
A16: Total steam condensed | B16: ='3 Node Calculations'!$D$119 -> 0.44166667 | C16: kg/s
A17: Total steam condensed | B17: ='3 Node Calculations'!$D$119*3600 -> 1590 | C17: kg/h
A19: WATER REMOVAL REQUIRED (EVAPORATION DUTY)
A20: Quantity | B20: Value | C20: Unit | D20: Basis / equation
A21: Water to evaporate = outlet flow - flow after evaporation | B21: ='3 Node Calculations'!$F$119*3600-'3 Node Calculations'!$G$12/'1 Inputs'!$B$30*3600 -> 1590 | C21: kg/h | D21: With target = inlet solids this equals exactly the steam condensed (whole-model check).
A22: Water to evaporate | B22: ='3 Node Calculations'!$F$119-'3 Node Calculations'!$G$12/'1 Inputs'!$B$30 -> 0.44166667 | C22: kg/s | D22: SI units.
A24: ENERGY
A25: Quantity | B25: Value | C25: Unit | D25: Basis / equation
A26: Enthalpy flow at inlet | B26: ='3 Node Calculations'!$G$13 -> 98.630301 | C26: kW | D26: Milk flow x c_p x inlet temperature (datum 0 degC).
A27: Enthalpy flow at outlet | B27: ='3 Node Calculations'!$J$119 -> 1315.9078 | C27: kW | D27: Last node of the energy balance.
A28: Enthalpy added by steam = steam flow x h_g | B28: ='3 Node Calculations'!$G$11*'2 Steam Properties'!$B$13 -> 1217.2775 | C28: kW | D28: Total enthalpy carried in by the steam.
A29: Heat transferred to milk = steam flow x (h_g - c_p x outlet T) | B29: ='3 Node Calculations'!$G$11*('2 Steam Properties'!$B$13-'1 Inputs'!$B$10*'3 Node Calculations'!$L$119) -> 1084.2406 | C29: kW | D29: Latent heat + condensate sensible heat down to the outlet temperature.
A30: latent = steam flow x h_fg | B30: ='3 Node Calculations'!$G$11*'2 Steam Properties'!$B$12 -> 921.14 | C30: kW | D30: Latent contribution.
A32: FLOW REGIME & NOZZLE DIAGNOSTICS
A33: Flow regime (Reynolds number)
A34: Quantity | B34: Value | C34: Unit | D34: Basis / equation
A35: Water dynamic viscosity at inlet temperature | B35: =0.00002414*10^(247.8/(('1 Inputs'!$B$8+273.15)-140)) -> 0.0014573013 | C35: Pa.s | D35: Vogel correlation for water, valid 0-100 degC. Milk treated as water.
A36: Water dynamic viscosity at outlet temperature | B36: =0.00002414*10^(247.8/(($B$6+273.15)-140)) -> 0.00038983613 | C36: Pa.s | D36: Same correlation at the outlet temperature.
A37: Reynolds number at inlet (cold) | B37: ='1 Inputs'!$B$11*'1 Inputs'!$B$6*'1 Inputs'!$B$24/$B$35 -> 68619.992 | C37: - | D37: Re = rho x velocity x diameter / viscosity.
A38: Reynolds number at outlet (hot) | B38: ='1 Inputs'!$B$11*$B$11*'1 Inputs'!$B$24/$B$36 -> 285368.49 | C38: - | D38: Outlet velocity and viscosity; Re is highest here.
A39: Flow regime at inlet | B39: =IF($B$37<2300,"Laminar",IF($B$37<4000,"Transitional","Turbulent")) -> Turbulent | C39: - | D39: Re<2300 laminar; 2300-4000 transitional; >4000 turbulent.
A40: Flow regime at outlet | B40: =IF($B$38<2300,"Laminar",IF($B$38<4000,"Transitional","Turbulent")) -> Turbulent | C40: - | D40: Same thresholds at the hot end.
A44: Choked steam velocity and nozzle limit
A45: Quantity | B45: Value | C45: Unit | D45: Basis / equation
A46: Isentropic exponent of dry saturated steam, k | B46: 1.135 | C46: - | D46: k = 1.135 for dry saturated steam (Eastop & McConkey); same as the cross-sectional model.
A47: Saturated vapour density at supply, rho0 = 1/v_g | B47: ='2 Steam Properties'!$B$14^-1 -> 3.1685678 | C47: kg/m3 | D47: Real steam density from the IAPWS-IF97 table (replaces the ideal-gas R.T0).
A48: Stagnation temperature, T0 | B48: ='2 Steam Properties'!$B$10+273.15 -> 431.98 | C48: K | D48: Steam saturation temperature at supply pressure, in kelvin.
A49: Choked (sonic) velocity at the throat, a* | B49: =SQRT($B$46*$B$51/$B$47*2/($B$46+1)) -> 448.70211 | C49: m/s | D49: a* = sqrt[ k p0/rho0 x 2/(k+1) ], the throat sound speed (same form as the cross-sectional model).
...

Sheet 5 Steam Sizing
A1: STEAM DEMAND CALCULATOR (REVERSE PROBLEM)
A4: TARGET
A5: Target outlet milk temperature | B5: 72 | C5: degC
A7: SIZING RESULTS
A8: Quantity | B8: Value | C8: Unit | D8: Basis / equation
A9: Required steam flow | B9: ='3 Node Calculations'!$G$10*'1 Inputs'!$B$10*('5 Steam Sizing'!$B$5-'1 Inputs'!$B$8)/('2 Steam Properties'!$B$13-'1 Inputs'!$B$10*'5 Steam Sizing'!$B$5) -> 0.4419806 | C9: kg/s | D9: Closed-form energy balance
A10: Required steam flow | B10: ='3 Node Calculations'!$G$10*'1 Inputs'!$B$10*('5 Steam Sizing'!$B$5-'1 Inputs'!$B$8)/('2 Steam Properties'!$B$13-'1 Inputs'!$B$10*'5 Steam Sizing'!$B$5)*3600 -> 1591.1302 | C10: kg/h | D10: Copy this value to '1 Inputs' steam mass flow to run the full model at this duty.
A11: Steam-to-milk ratio | B11: ='1 Inputs'!$B$10*('5 Steam Sizing'!$B$5-'1 Inputs'!$B$8)/('2 Steam Properties'!$B$13-'1 Inputs'!$B$10*'5 Steam Sizing'!$B$5) -> 0.11254944 | C11: kg/kg | D11: Rule-of-thumb check: ~1% steam per ~6 K rise.
A12: Resulting outlet mass flow | B12: =('3 Node Calculations'!$G$10+'3 Node Calculations'!$G$10*'1 Inputs'!$B$10*('5 Steam Sizing'!$B$5-'1 Inputs'!$B$8)/('2 Steam Properties'!$B$13-'1 Inputs'!$B$10*'5 Steam Sizing'!$B$5))*3600 -> 15728.297 | C12: kg/h | D12: Milk flow + required steam flow.
A13: Resulting outlet solids concentration | B13: ='3 Node Calculations'!$G$12/('3 Node Calculations'!$G$10+'3 Node Calculations'!$G$10*'1 Inputs'!$B$10*('5 Steam Sizing'!$B$5-'1 Inputs'!$B$8)/('2 Steam Properties'!$B$13-'1 Inputs'!$B$10*'5 Steam Sizing'!$B$5)) -> 0.10786038 | C13: kg/kg | D13: Dilution at the sized steam rate.
A14: Water to evaporate at this duty | B14: =('3 Node Calculations'!$G$10+'3 Node Calculations'!$G$10*'1 Inputs'!$B$10*('5 Steam Sizing'!$B$5-'1 Inputs'!$B$8)/('2 Steam Properties'!$B$13-'1 Inputs'!$B$10*'5 Steam Sizing'!$B$5))*3600-'3 Node Calculations'!$G$12/'1 Inputs'!$B$30*3600 -> 1591.1302 | C14: kg/h | D14: Outlet flow - solids flow / target solids; equals the required steam flow when target = inlet solids.
A15: Nozzle velocity at required flow | B15: ='3 Node Calculations'!$G$10*'1 Inputs'!$B$10*('5 Steam Sizing'!$B$5-'1 Inputs'!$B$8)/('2 Steam Properties'!$B$13-'1 Inputs'!$B$10*'5 Steam Sizing'!$B$5)*'2 Steam Properties'!$B$14/'3 Node Calculations'!$G$9 -> 7104.1204 | C15: m/s | D15: Required flow x v_g / nozzle area. Compare against the sonic limit.
A17: FEASIBILITY CHECKS
A18: Quantity | B18: Value | C18: Unit | D18: Basis / equation
A19: Target above inlet temperature | B19: =IF('5 Steam Sizing'!$B$5>'1 Inputs'!$B$8,"OK","TARGET BELOW INLET — no heating needed") -> OK | C19: - | D19: Steam injection can only heat.
A20: Target below steam temperature | B20: =IF('5 Steam Sizing'!$B$5<'2 Steam Properties'!$B$10,"OK","INFEASIBLE — mixture cannot exceed the steam saturation temperature; raise steam pressure") -> OK | C20: - | D20: A condensing injector can never heat the milk above the steam saturation temperature; approaching it demands rapidly increasing steam flow.
A21: Nozzle below choking limit at required flow | B21: =IF($B$10<='4 Results'!$B$53,"OK","CHOKED: enlarge the bore, add orifices or raise the pressure") -> CHOKED: enlarge the bore, add orifices or raise the pressure | C21: - | D21: Checks the required flow against the choked capacity of the nozzle on '4 Results'.

Sheet 6 Documentation
A1: MODEL DOCUMENTATION — EQUATIONS, ASSUMPTIONS, EXTENSION GUIDE
A3: 1. ASSUMPTIONS (each is required by at least one equation below)
A4: One-dimensional plug flow, one value per node, uniform over each cross-section.
A5: Steady state, no accumulation terms (d/dt = 0).
A6: Milk treated thermodynamically as pure water — c_p, density of water; fats/proteins/solids ignored in the energy balance.
A7: No pressure drop; constant pipe diameter; uniform velocity.
A8: Adiabatic pipe — no heat-loss term.
A9: Steam condenses immediately at the injection point with complete mixing — all steam enters one node.
A10: Dry saturated steam at supply pressure — properties from the table on sheet 2.
A11: Kinetic and potential energy neglected — enthalpy is the only energy carrier.
A12: Milk solids inert and conserved — constant solids mass flow.
A14: 3. FEED SPECIFICATION BY VELOCITY
... A93: - Standard dairy processing criteria for HTST pasteurisation (72 degC/15 s) and UHT sterilisation (>=138 degC/2 s).
